<?xml version="1.0"?>
<robot name="turtle">
  <!-- Base Link -->
  <link name="base_link">
    <inertial>
      <mass value="1.0"/>
      <origin xyz="0 0 0" rpy="0 0 0"/>
      <inertia ixx="0.01" ixy="0" ixz="0" iyy="0.01" iyz="0" izz="0.01"/>
    </inertial>
    <visual>
      <origin xyz="0 0 0" rpy="0 0 0"/>
      <geometry>
        <cylinder radius="0.2" length="0.1"/>
      </geometry>
      <material name="green">
        <color rgba="0.0 0.8 0.0 1.0"/>
      </material>
    </visual>
    <collision>
      <origin xyz="0 0 0" rpy="0 0 0"/>
      <geometry>
        <cylinder radius="0.2" length="0.1"/>
      </geometry>
    </collision>
  </link>
  
  <!-- Head Link -->
  <link name="head">
    <inertial>
      <mass value="0.1"/>
      <origin xyz="0 0 0" rpy="0 0 0"/>
      <inertia ixx="0.001" ixy="0" ixz="0" iyy="0.001" iyz="0" izz="0.001"/>
    </inertial>
    <visual>
      <origin xyz="0 0 0" rpy="0 0 0"/>
      <geometry>
        <sphere radius="0.1"/>
      </geometry>
      <material name="green">
        <color rgba="0.0 0.8 0.0 1.0"/>
      </material>
    </visual>
    <collision>
      <origin xyz="0 0 0" rpy="0 0 0"/>
      <geometry>
        <sphere radius="0.1"/>
      </geometry>
    </collision>
  </link>
  
  <!-- Joint between base and head -->
  <joint name="base_to_head" type="fixed">
    <parent link="base_link"/>
    <child link="head"/>
    <origin xyz="0.15 0 0.05" rpy="0 0 0"/>
  </joint>
  
  <!-- Right Leg Link -->
  <link name="right_leg">
    <inertial>
      <mass value="0.1"/>
      <origin xyz="0 0 0" rpy="0 0 0"/>
      <inertia ixx="0.001" ixy="0" ixz="0" iyy="0.001" iyz="0" izz="0.001"/>
    </inertial>
    <visual>
      <origin xyz="0 0 0" rpy="0 0 0"/>
      <geometry>
        <box size="0.1 0.05 0.05"/>
      </geometry>
      <material name="green">
        <color rgba="0.0 0.8 0.0 1.0"/>
      </material>
    </visual>
    <collision>
      <origin xyz="0 0 0" rpy="0 0 0"/>
      <geometry>
        <box size="0.1 0.05 0.05"/>
      </geometry>
    </collision>
  </link>
  
  <!-- Joint between base and right leg -->
  <joint name="base_to_right_leg" type="fixed">
    <parent link="base_link"/>
    <child link="right_leg"/>
    <origin xyz="0 -0.15 -0.05" rpy="0 0 0"/>
  </joint>
  
  <!-- Left Leg Link -->
  <link name="left_leg">
    <inertial>
      <mass value="0.1"/>
      <origin xyz="0 0 0" rpy="0 0 0"/>
      <inertia ixx="0.001" ixy="0" ixz="0" iyy="0.001" iyz="0" izz="0.001"/>
    </inertial>
    <visual>
      <origin xyz="0 0 0" rpy="0 0 0"/>
      <geometry>
        <box size="0.1 0.05 0.05"/>
      </geometry>
      <material name="green">
        <color rgba="0.0 0.8 0.0 1.0"/>
      </material>
    </visual>
    <collision>
      <origin xyz="0 0 0" rpy="0 0 0"/>
      <geometry>
        <box size="0.1 0.05 0.05"/>
      </geometry>
    </collision>
  </link>
  
  <!-- Joint between base and left leg -->
  <joint name="base_to_left_leg" type="fixed">
    <parent link="base_link"/>
    <child link="left_leg"/>
    <origin xyz="0 0.15 -0.05" rpy="0 0 0"/>
  </joint>
  
  <!-- Gazebo plugin for differential drive -->
  <gazebo>
    <plugin name="differential_drive_controller" filename="libgazebo_ros_diff_drive.so">
      <updateRate>100.0</updateRate>
      <leftJoint>base_to_left_wheel</leftJoint>
      <rightJoint>base_to_right_wheel</rightJoint>
      <wheelSeparation>0.3</wheelSeparation>
      <wheelDiameter>0.1</wheelDiameter>
      <wheelAcceleration>1.0</wheelAcceleration>
      <wheelTorque>10</wheelTorque>
      <commandTopic>turtle/cmd_vel</commandTopic>
      <odometryTopic>turtle/odom</odometryTopic>
      <odometryFrame>odom</odometryFrame>
      <robotBaseFrame>base_link</robotBaseFrame>
      <publishWheelTF>true</publishWheelTF>
      <publishOdomTF>true</publishOdomTF>
      <publishWheelJointState>true</publishWheelJointState>
      <legacyMode>false</legacyMode>
      <rosDebugLevel>na</rosDebugLevel>
      <publishTf>1</publishTf>
    </plugin>
  </gazebo>
  
  <!-- Left Wheel Link -->
  <link name="left_wheel">
    <inertial>
      <mass value="0.1"/>
      <origin xyz="0 0 0" rpy="0 0 0"/>
      <inertia ixx="0.001" ixy="0" ixz="0" iyy="0.001" iyz="0" izz="0.001"/>
    </inertial>
    <visual>
      <origin xyz="0 0 0" rpy="1.5707 0 0"/>
      <geometry>
        <cylinder radius="0.05" length="0.02"/>
      </geometry>
      <material name="black">
        <color rgba="0.0 0.0 0.0 1.0"/>
      </material>
    </visual>
    <collision>
      <origin xyz="0 0 0" rpy="1.5707 0 0"/>
      <geometry>
        <cylinder radius="0.05" length="0.02"/>
      </geometry>
    </collision>
  </link>
  
  <!-- Joint between base and left wheel -->
  <joint name="base_to_left_wheel" type="continuous">
    <parent link="base_link"/>
    <child link="left_wheel"/>
    <origin xyz="-0.1 0.15 -0.05" rpy="0 0 0"/>
    <axis xyz="0 1 0"/>
  </joint>
  
  <!-- Right Wheel Link -->
  <link name="right_wheel">
    <inertial>
      <mass value="0.1"/>
      <origin xyz="0 0 0" rpy="0 0 0"/>
      <inertia ixx="0.001" ixy="0" ixz="0" iyy="0.001" iyz="0" izz="0.001"/>
    </inertial>
    <visual>
      <origin xyz="0 0 0" rpy="1.5707 0 0"/>
      <geometry>
        <cylinder radius="0.05" length="0.02"/>
      </geometry>
      <material name="black">
        <color rgba="0.0 0.0 0.0 1.0"/>
      </material>
    </visual>
    <collision>
      <origin xyz="0 0 0" rpy="1.5707 0 0"/>
      <geometry>
        <cylinder radius="0.05" length="0.02"/>
      </geometry>
    </collision>
  </link>
  
  <!-- Joint between base and right wheel -->
  <joint name="base_to_right_wheel" type="continuous">
    <parent link="base_link"/>
    <child link="right_wheel"/>
    <origin xyz="-0.1 -0.15 -0.05" rpy="0 0 0"/>
    <axis xyz="0 1 0"/>
  </joint>
</robot>